[2024-11-10T00:45:13.466+0000] {task_context_logger.py:104} ERROR - Executor reports task instance <TaskInstance: Stock_Prediction.predict manual__2024-11-10T00:42:49.178198+00:00 [queued]> finished (failed) although the task says it's queued. (Info: None) Was the task killed externally?
