[2024-11-10T02:14:37.433+0000] {task_context_logger.py:104} ERROR - Executor reports task instance <TaskInstance: Stock_Data_ETL.initialize_target_table manual__2024-11-10T02:14:36.050545+00:00 [queued]> finished (failed) although the task says it's queued. (Info: None) Was the task killed externally?
